Workbook
Name Institutos: Lista!$A$2:$A$34

Sheet Centralizador 3er año Maña
F3: CENTRALIZADOR DE CALIFICACIONES
S5: TURNO: | U5: MAÑANA
C6: INSTITUCIÓN: | E6: INSTITUTO TECNICO DE EDUCACIÓN SUPERIOR "NOVELL" | Q6: R.M. | R6: 0906/02 | S6: CARÁCTER: | U6: PRIVADO
C7: GESTIÓN: | E7: 2020 | F7: CÉDULA DE IDENTIDAD | G7: COA-301 | H7: COC-302 | I7: COG-303 | J7: CEP-304 | K7: CSH-305 | L7: GCI-306 | M7: AEF-307 | N7: TMG-308 | V7: OBSERVACIONES
G8: CONTABILIDAD AGROPECUARIA | H8: CONTABILIDAD DE COSTOS II | I8: CONTABILIDAD GUBERNAMENTAL | J8: CONTABILIDAD EXTRACTIVA (MINERA, PETROLERA Y FORESTAL) | K8: CONTABILIDAD DE SERVICIOS (CONSTRUCCIÓN, HOTELERÍA Y TRANSPORTE) | L8: GABINETA CONTABLE INFORMÁTICO | M8: ANÁLISIS E INTERPRETACIONES DE ESTADOS FINANCIEROS | N8: TALLER DE MODALIDAD DE GRADUACIÓN
C9: NIVEL: | E9: TECNICO SUPERIOR
C10: CARRERA: | E10: CONTADURIA GENERAL
C11: RÉGIMEN: | E11: ANUAL
C12: CURSO: | E12: TERCER AÑO - A
C13: N° | D13: NÓMINA ESTUDIANTES
C14: 1 | D14: =+'COA-301'!D13:E13 -> 0 | G14: =+'COA-301'!H13 -> 0 | H14: =+'COC-302'!H13 -> 0 | I14: =+'COG-303'!H13 -> 0 | J14: =+'CEP.304'!H13 -> 0 | K14: =+'CSH-305'!H13 -> 0 | L14: =+'GCI-306'!H13 -> 0 | M14: =+'AEF-307'!H13 -> 0 | V14: =IF(M14=0,"Abandono",IF(AVERAGE(G14:M14)>=61,"Aprobado","Reprobado")) -> Abandono
C15: 2 | D15: =+'COA-301'!D14:E14 -> 0 | G15: =+'COA-301'!H14 -> 0 | H15: =+'COC-302'!H14 -> 0 | I15: =+'COG-303'!H14 -> 0 | J15: =+'CEP.304'!H14 -> 0 | K15: =+'CSH-305'!H14 -> 0 | L15: =+'GCI-306'!H14 -> 0 | M15: =+'AEF-307'!H14 -> 0 | V15: =IF(M15=0,"Abandono",IF(AVERAGE(G15:M15)>=61,"Aprobado","Reprobado")) -> Abandono
C16: 3 | D16: =+'COA-301'!D15:E15 -> 0 | G16: =+'COA-301'!H15 -> 0 | H16: =+'COC-302'!H15 -> 0 | I16: =+'COG-303'!H15 -> 0 | J16: =+'CEP.304'!H15 -> 0 | K16: =+'CSH-305'!H15 -> 0 | L16: =+'GCI-306'!H15 -> 0 | M16: =+'AEF-307'!H15 -> 0 | V16: =IF(M16=0,"Abandono",IF(AVERAGE(G16:M16)>=61,"Aprobado","Reprobado")) -> Abandono
C17: 4 | D17: =+'COA-301'!D16:E16 -> 0 | G17: =+'COA-301'!H16 -> 0 | H17: =+'COC-302'!H16 -> 0 | I17: =+'COG-303'!H16 -> 0 | J17: =+'CEP.304'!H16 -> 0 | K17: =+'CSH-305'!H16 -> 0 | L17: =+'GCI-306'!H16 -> 0 | M17: =+'AEF-307'!H16 -> 0 | V17: =IF(M17=0,"Abandono",IF(AVERAGE(G17:M17)>=61,"Aprobado","Reprobado")) -> Abandono
C18: 5 | D18: =+'COA-301'!D17:E17 -> 0 | G18: =+'COA-301'!H17 -> 0 | H18: =+'COC-302'!H17 -> 0 | I18: =+'COG-303'!H17 -> 0 | J18: =+'CEP.304'!H17 -> 0 | K18: =+'CSH-305'!H17 -> 0 | L18: =+'GCI-306'!H17 -> 0 | M18: =+'AEF-307'!H17 -> 0 | V18: =IF(M18=0,"Abandono",IF(AVERAGE(G18:M18)>=61,"Aprobado","Reprobado")) -> Abandono
C19: 6 | D19: =+'COA-301'!D18:E18 -> 0 | G19: =+'COA-301'!H18 -> 0 | H19: =+'COC-302'!H18 -> 0 | I19: =+'COG-303'!H18 -> 0 | J19: =+'CEP.304'!H18 -> 0 | K19: =+'CSH-305'!H18 -> 0 | L19: =+'GCI-306'!H18 -> 0 | M19: =+'AEF-307'!H18 -> 0 | V19: =IF(M19=0,"Abandono",IF(AVERAGE(G19:M19)>=61,"Aprobado","Reprobado")) -> Abandono
C20: 7 | D20: =+'COA-301'!D19:E19 -> 0 | G20: =+'COA-301'!H19 -> 0 | H20: =+'COC-302'!H19 -> 0 | I20: =+'COG-303'!H19 -> 0 | J20: =+'CEP.304'!H19 -> 0 | K20: =+'CSH-305'!H19 -> 0 | L20: =+'GCI-306'!H19 -> 0 | M20: =+'AEF-307'!H19 -> 0 | V20: =IF(M20=0,"Abandono",IF(AVERAGE(G20:M20)>=61,"Aprobado","Reprobado")) -> Abandono
C21: 8 | D21: =+'COA-301'!D20:E20 -> 0 | G21: =+'COA-301'!H20 -> 0 | H21: =+'COC-302'!H20 -> 0 | I21: =+'COG-303'!H20 -> 0 | J21: =+'CEP.304'!H20 -> 0 | K21: =+'CSH-305'!H20 -> 0 | L21: =+'GCI-306'!H20 -> 0 | M21: =+'AEF-307'!H20 -> 0 | V21: =IF(M21=0,"Abandono",IF(AVERAGE(G21:M21)>=61,"Aprobado","Reprobado")) -> Abandono
C22: 9 | D22: =+'COA-301'!D21:E21 -> 0 | G22: =+'COA-301'!H21 -> 0 | H22: =+'COC-302'!H21 -> 0 | I22: =+'COG-303'!H21 -> 0 | J22: =+'CEP.304'!H21 -> 0 | K22: =+'CSH-305'!H21 -> 0 | L22: =+'GCI-306'!H21 -> 0 | M22: =+'AEF-307'!H21 -> 0 | V22: =IF(M22=0,"Abandono",IF(AVERAGE(G22:M22)>=61,"Aprobado","Reprobado")) -> Abandono
C23: 10 | D23: =+'COA-301'!D22:E22 -> 0 | G23: =+'COA-301'!H22 -> 0 | H23: =+'COC-302'!H22 -> 0 | I23: =+'COG-303'!H22 -> 0 | J23: =+'CEP.304'!H22 -> 0 | K23: =+'CSH-305'!H22 -> 0 | L23: =+'GCI-306'!H22 -> 0 | M23: =+'AEF-307'!H22 -> 0 | V23: =IF(M23=0,"Abandono",IF(AVERAGE(G23:M23)>=61,"Aprobado","Reprobado")) -> Abandono
C24: 11 | D24: =+'COA-301'!D23:E23 -> 0 | G24: =+'COA-301'!H23 -> 0 | H24: =+'COC-302'!H23 -> 0 | I24: =+'COG-303'!H23 -> 0 | J24: =+'CEP.304'!H23 -> 0 | K24: =+'CSH-305'!H23 -> 0 | L24: =+'GCI-306'!H23 -> 0 | M24: =+'AEF-307'!H23 -> 0 | V24: =IF(M24=0,"Abandono",IF(AVERAGE(G24:M24)>=61,"Aprobado","Reprobado")) -> Abandono
C25: 12 | D25: =+'COA-301'!D24:E24 -> 0 | G25: =+'COA-301'!H24 -> 0 | H25: =+'COC-302'!H24 -> 0 | I25: =+'COG-303'!H24 -> 0 | J25: =+'CEP.304'!H24 -> 0 | K25: =+'CSH-305'!H24 -> 0 | L25: =+'GCI-306'!H24 -> 0 | M25: =+'AEF-307'!H24 -> 0 | V25: =IF(M25=0,"Abandono",IF(AVERAGE(G25:M25)>=61,"Aprobado","Reprobado")) -> Abandono
... C37: 24 | D37: =+'COA-301'!D36:E36 -> 0 | G37: =+'COA-301'!H36 -> 0 | H37: =+'COC-302'!H36 -> 0 | I37: =+'COG-303'!H36 -> 0 | J37: =+'CEP.304'!H36 -> 0 | K37: =+'CSH-305'!H36 -> 0 | L37: =+'GCI-306'!H36 -> 0 | M37: =+'AEF-307'!H36 -> 0 | V37: =IF(M37=0,"Abandono",IF(AVERAGE(G37:M37)>=61,"Aprobado","Reprobado")) -> Abandono
C44: *En observaciones tomar en cuenta: Aprobado, Reprobado y Abandono
E48: Firma y Sello | H48: Sello de la | K48: Firma y Sello
E49: DIRECTOR ACADEMICO | H49: institución | K49: Vo.Bo. RECTOR
O50: ELABORADO POR:
O51: NOMBRE: | Q51: Profa. Rillma Marina Arandia Gomez
O52: CARGO: | Q52: DIRECTORA ADMINISTRATIVA
D53: DETALLE | G53: CANTIDAD | H53: PORCENT. | O53: FIRMA:
D54: ESTUDIANTES INSCRITOS | G54: =COUNT(C14:C41) -> 24 | H54: 1 | O54: FECHA: | Q54: ORURO, 05 DE DICIEMBRE DE 2019
D55: ESTUDIANTES APROBADOS | G55: =COUNTIF(V14:V43,"Aprobado") -> 0 | H55: =(G55*H54)/G54 -> 0
D56: ESTUDIANTES REPROBADOS | G56: =COUNTIF(V14:V43,"Reprobado") -> 0 | H56: =(G56*H54)/G54 -> 0
D57: ABADONO | G57: =COUNTIF(V14:V43,"Abandono") -> 24 | H57: =(G57*H54)/G54 -> 1

Sheet COA-301
A4: INSTITUTO TECNICO DE EDUCACIÓN SUPERIOR "NOVELL"
D5: CARRERA: | E5: CONTADURÍA GENERAL
D6: MENCIÓN:
D7: ÁREA: | E7: COMERCIAL Y SERVICIOS
D8: MATERIA: | E8: CONTABILIDAD AGROPECUARIA | I8: SIGLA: | J8: COA-301
D9: DOCENTE:
D10: AÑO/SEMESTRE: | E10: TERCER AÑO | I10: GESTIÓN: | J10: 2022
C12: Nro. | D12: Apellidos y Nombres | F12: Prom. Ev. Teórica | G12: Prom. Eval. Práctica | H12: Calificación Final | I12: Prueba de Recuper. | J12: Observación
C13: 1 | H13: =+F13+G13 -> 0 | J13: =IF(H13=0,"Abandono",IF(H13>=61,"Aprobado","Reprobado")) -> Abandono
C14: 2 | H14: =+F14+G14 -> 0 | J14: =IF(H14=0,"Abandono",IF(H14>=61,"Aprobado","Reprobado")) -> Abandono
C15: 3 | H15: =+F15+G15 -> 0 | J15: =IF(H15=0,"Abandono",IF(H15>=61,"Aprobado","Reprobado")) -> Abandono
C16: 4 | H16: =+F16+G16 -> 0 | J16: =IF(H16=0,"Abandono",IF(H16>=61,"Aprobado","Reprobado")) -> Abandono
C17: 5 | H17: =+F17+G17 -> 0 | J17: =IF(H17=0,"Abandono",IF(H17>=61,"Aprobado","Reprobado")) -> Abandono
C18: 6 | H18: =+F18+G18 -> 0 | J18: =IF(H18=0,"Abandono",IF(H18>=61,"Aprobado","Reprobado")) -> Abandono
C19: 7 | H19: =+F19+G19 -> 0 | J19: =IF(H19=0,"Abandono",IF(H19>=61,"Aprobado","Reprobado")) -> Abandono
C20: 8 | H20: =+F20+G20 -> 0 | J20: =IF(H20=0,"Abandono",IF(H20>=61,"Aprobado","Reprobado")) -> Abandono
C21: 9 | H21: =+F21+G21 -> 0 | J21: =IF(H21=0,"Abandono",IF(H21>=61,"Aprobado","Reprobado")) -> Abandono
C22: 10 | H22: =+F22+G22 -> 0 | J22: =IF(H22=0,"Abandono",IF(H22>=61,"Aprobado","Reprobado")) -> Abandono
C23: 11 | H23: =+F23+G23 -> 0 | J23: =IF(H23=0,"Abandono",IF(H23>=61,"Aprobado","Reprobado")) -> Abandono
C24: 12 | H24: =+F24+G24 -> 0 | J24: =IF(H24=0,"Abandono",IF(H24>=61,"Aprobado","Reprobado")) -> Abandono
... C36: 24 | H36: =+F36+G36 -> 0 | J36: =IF(H36=0,"Abandono",IF(H36>=61,"Aprobado","Reprobado")) -> Abandono
G50: RESUMEN | I50: TOTAL | J50: PORCENTAJE
G51: Inscritos | I51: =COUNT(C13:C47) -> 24 | J51: 1
G52: Aprobados | I52: =COUNTIF(J13:K47,"Aprobado") -> 0 | J52: =(I52*J51)/I51 -> 0
G53: Reprobados | I53: =COUNTIF(J13:K47,"Reprobado") -> 0 | J53: =(I53*J51)/I51 -> 0
G54: Abandonos | I54: =COUNTIF(J13:J47,"Abandono") -> 24 | J54: =(I54*J51)/I51 -> 1
B61: Firma y Sello | F61: Sello de la | I61: Firma y Sello
B62: DIRECTOR ACADEMICO | F62: institución | I62: DOCENTE DE LA MATERIA

Sheet COC-302
A4: INSTITUTO TECNICO DE EDUCACIÓN SUPERIOR "NOVELL"
D5: CARRERA: | E5: CONTADURÍA GENERAL
D6: MENCIÓN:
D7: ÁREA: | E7: COMERCIAL Y SERVICIOS
D8: MATERIA: | E8: CONTABILIDAD DE COSTOS II | I8: SIGLA: | J8: COC-302
D9: DOCENTE:
D10: AÑO/SEMESTRE: | E10: =+'COA-301'!E10:H10 -> TERCER AÑO | I10: GESTIÓN: | J10: =+'COA-301'!J10:K10 -> 2022
C12: Nro. | D12: Apellidos y Nombres | F12: Prom. Ev. Teórica | G12: Prom. Eval. Práctica | H12: Calificación Final | I12: Prueba de Recuper. | J12: Observación
C13: 1 | D13: =+'COA-301'!D13:E13 -> 0 | H13: =+F13+G13 -> 0 | J13: =IF(H13=0,"Abandono",IF(H13>=61,"Aprobado","Reprobado")) -> Abandono
C14: 2 | D14: =+'COA-301'!D14:E14 -> 0 | H14: =+F14+G14 -> 0 | J14: =IF(H14=0,"Abandono",IF(H14>=61,"Aprobado","Reprobado")) -> Abandono
C15: 3 | D15: =+'COA-301'!D15:E15 -> 0 | H15: =+F15+G15 -> 0 | J15: =IF(H15=0,"Abandono",IF(H15>=61,"Aprobado","Reprobado")) -> Abandono
C16: 4 | D16: =+'COA-301'!D16:E16 -> 0 | H16: =+F16+G16 -> 0 | J16: =IF(H16=0,"Abandono",IF(H16>=61,"Aprobado","Reprobado")) -> Abandono
C17: 5 | D17: =+'COA-301'!D17:E17 -> 0 | H17: =+F17+G17 -> 0 | J17: =IF(H17=0,"Abandono",IF(H17>=61,"Aprobado","Reprobado")) -> Abandono
C18: 6 | D18: =+'COA-301'!D18:E18 -> 0 | H18: =+F18+G18 -> 0 | J18: =IF(H18=0,"Abandono",IF(H18>=61,"Aprobado","Reprobado")) -> Abandono
C19: 7 | D19: =+'COA-301'!D19:E19 -> 0 | H19: =+F19+G19 -> 0 | J19: =IF(H19=0,"Abandono",IF(H19>=61,"Aprobado","Reprobado")) -> Abandono
C20: 8 | D20: =+'COA-301'!D20:E20 -> 0 | H20: =+F20+G20 -> 0 | J20: =IF(H20=0,"Abandono",IF(H20>=61,"Aprobado","Reprobado")) -> Abandono
C21: 9 | D21: =+'COA-301'!D21:E21 -> 0 | H21: =+F21+G21 -> 0 | J21: =IF(H21=0,"Abandono",IF(H21>=61,"Aprobado","Reprobado")) -> Abandono
C22: 10 | D22: =+'COA-301'!D22:E22 -> 0 | H22: =+F22+G22 -> 0 | J22: =IF(H22=0,"Abandono",IF(H22>=61,"Aprobado","Reprobado")) -> Abandono
C23: 11 | D23: =+'COA-301'!D23:E23 -> 0 | H23: =+F23+G23 -> 0 | J23: =IF(H23=0,"Abandono",IF(H23>=61,"Aprobado","Reprobado")) -> Abandono
C24: 12 | D24: =+'COA-301'!D24:E24 -> 0 | H24: =+F24+G24 -> 0 | J24: =IF(H24=0,"Abandono",IF(H24>=61,"Aprobado","Reprobado")) -> Abandono
... C36: 24 | D36: =+'COA-301'!D36:E36 -> 0 | H36: =+F36+G36 -> 0 | J36: =IF(H36=0,"Abandono",IF(H36>=61,"Aprobado","Reprobado")) -> Abandono
H37: =+F37+G37 -> 0
H38: =+F38+G38 -> 0
H39: =+F39+G39 -> 0
H40: =+F40+G40 -> 0
H41: =+F41+G41 -> 0
H42: =+F42+G42 -> 0
H43: =+F43+G43 -> 0
H44: =+F44+G44 -> 0
H45: =+F45+G45 -> 0
H46: =+F46+G46 -> 0
H47: =+F47+G47 -> 0
G50: RESUMEN | I50: TOTAL | J50: PORCENTAJE
G51: Inscritos | I51: =COUNT(C13:C47) -> 24 | J51: 1
G52: Aprobados | I52: =COUNTIF(J13:K47,"Aprobado") -> 0 | J52: =(I52*J51)/I51 -> 0
G53: Reprobados | I53: =COUNTIF(J13:K47,"Reprobado") -> 0 | J53: =(I53*J51)/I51 -> 0
G54: Abandonos | I54: =COUNTIF(J13:J47,"Abandono") -> 24 | J54: =(I54*J51)/I51 -> 1
B61: Firma y Sello | F61: Sello de la | I61: Firma y Sello
B62: DIRECTOR ACADEMICO | F62: institución | I62: DOCENTE DE LA MATERIA

Sheet COG-303
A4: INSTITUTO TECNICO DE EDUCACIÓN SUPERIOR "NOVELL"
D5: CARRERA: | E5: CONTADURÍA GENERAL
D6: MENCIÓN:
D7: ÁREA: | E7: COMERCIAL Y SERVICIOS
D8: MATERIA: | E8: CONTABILIDAD GUBERNAMENTAL | I8: SIGLA: | J8: COG-303
D9: DOCENTE:
D10: AÑO/SEMESTRE: | E10: =+'COA-301'!E10:H10 -> TERCER AÑO | I10: GESTIÓN: | J10: =+'COA-301'!J10:K10 -> 2022
C12: Nro. | D12: Apellidos y Nombres | F12: Prom. Ev. Teórica | G12: Prom. Eval. Práctica | H12: Calificación Final | I12: Prueba de Recuper. | J12: Observación
C13: 1 | D13: =+'COA-301'!D13:E13 -> 0 | H13: =+F13+G13 -> 0 | J13: =IF(H13=0,"Abandono",IF(H13>=61,"Aprobado","Reprobado")) -> Abandono
C14: 2 | D14: =+'COA-301'!D14:E14 -> 0 | H14: =+F14+G14 -> 0 | J14: =IF(H14=0,"Abandono",IF(H14>=61,"Aprobado","Reprobado")) -> Abandono
C15: 3 | D15: =+'COA-301'!D15:E15 -> 0 | H15: =+F15+G15 -> 0 | J15: =IF(H15=0,"Abandono",IF(H15>=61,"Aprobado","Reprobado")) -> Abandono
C16: 4 | D16: =+'COA-301'!D16:E16 -> 0 | H16: =+F16+G16 -> 0 | J16: =IF(H16=0,"Abandono",IF(H16>=61,"Aprobado","Reprobado")) -> Abandono
C17: 5 | D17: =+'COA-301'!D17:E17 -> 0 | H17: =+F17+G17 -> 0 | J17: =IF(H17=0,"Abandono",IF(H17>=61,"Aprobado","Reprobado")) -> Abandono
C18: 6 | D18: =+'COA-301'!D18:E18 -> 0 | H18: =+F18+G18 -> 0 | J18: =IF(H18=0,"Abandono",IF(H18>=61,"Aprobado","Reprobado")) -> Abandono
C19: 7 | D19: =+'COA-301'!D19:E19 -> 0 | H19: =+F19+G19 -> 0 | J19: =IF(H19=0,"Abandono",IF(H19>=61,"Aprobado","Reprobado")) -> Abandono
C20: 8 | D20: =+'COA-301'!D20:E20 -> 0 | H20: =+F20+G20 -> 0 | J20: =IF(H20=0,"Abandono",IF(H20>=61,"Aprobado","Reprobado")) -> Abandono
C21: 9 | D21: =+'COA-301'!D21:E21 -> 0 | H21: =+F21+G21 -> 0 | J21: =IF(H21=0,"Abandono",IF(H21>=61,"Aprobado","Reprobado")) -> Abandono
C22: 10 | D22: =+'COA-301'!D22:E22 -> 0 | H22: =+F22+G22 -> 0 | J22: =IF(H22=0,"Abandono",IF(H22>=61,"Aprobado","Reprobado")) -> Abandono
C23: 11 | D23: =+'COA-301'!D23:E23 -> 0 | H23: =+F23+G23 -> 0 | J23: =IF(H23=0,"Abandono",IF(H23>=61,"Aprobado","Reprobado")) -> Abandono
C24: 12 | D24: =+'COA-301'!D24:E24 -> 0 | H24: =+F24+G24 -> 0 | J24: =IF(H24=0,"Abandono",IF(H24>=61,"Aprobado","Reprobado")) -> Abandono
... C36: 24 | D36: =+'COA-301'!D36:E36 -> 0 | H36: =+F36+G36 -> 0 | J36: =IF(H36=0,"Abandono",IF(H36>=61,"Aprobado","Reprobado")) -> Abandono
H37: =+F37+G37 -> 0
H38: =+F38+G38 -> 0
H39: =+F39+G39 -> 0
H40: =+F40+G40 -> 0
H41: =+F41+G41 -> 0
H42: =+F42+G42 -> 0
H43: =+F43+G43 -> 0
H44: =+F44+G44 -> 0
H45: =+F45+G45 -> 0
H46: =+F46+G46 -> 0
H47: =+F47+G47 -> 0
G50: RESUMEN | I50: TOTAL | J50: PORCENTAJE
G51: Inscritos | I51: =COUNT(C13:C47) -> 24 | J51: 1
G52: Aprobados | I52: =COUNTIF(J13:K47,"Aprobado") -> 0 | J52: =(I52*J51)/I51 -> 0
G53: Reprobados | I53: =COUNTIF(J13:K47,"Reprobado") -> 0 | J53: =(I53*J51)/I51 -> 0
G54: Abandonos | I54: =COUNTIF(J13:J47,"Abandono") -> 24 | J54: =(I54*J51)/I51 -> 1
B61: Firma y Sello | F61: Sello de la | I61: Firma y Sello
B62: DIRECTOR ACADEMICO | F62: institución | I62: DOCENTE DE LA MATERIA

Sheet CEP.304
A4: INSTITUTO TECNICO DE EDUCACIÓN SUPERIOR "NOVELL"
D5: CARRERA: | E5: CONTADURÍA GENERAL
D6: MENCIÓN:
D7: ÁREA: | E7: COMERCIAL Y SERVICIOS
D8: MATERIA: | E8: CONTABILIDAD EXTRACTIVA (Minera, Petrolera y Forestal) | I8: SIGLA: | J8: CEP-304
D9: DOCENTE:
D10: AÑO/SEMESTRE: | E10: =+'COA-301'!E10:H10 -> TERCER AÑO | I10: GESTIÓN: | J10: =+'COA-301'!J10:K10 -> 2022
C12: Nro. | D12: Apellidos y Nombres | F12: Prom. Ev. Teórica | G12: Prom. Eval. Práctica | H12: Calificación Final | I12: Prueba de Recuper. | J12: Observación
C13: 1 | D13: =+'COA-301'!D13:E13 -> 0 | H13: =+F13+G13 -> 0 | J13: =IF(H13=0,"Abandono",IF(H13>=61,"Aprobado","Reprobado")) -> Abandono
C14: 2 | D14: =+'COA-301'!D14:E14 -> 0 | H14: =+F14+G14 -> 0 | J14: =IF(H14=0,"Abandono",IF(H14>=61,"Aprobado","Reprobado")) -> Abandono
C15: 3 | D15: =+'COA-301'!D15:E15 -> 0 | H15: =+F15+G15 -> 0 | J15: =IF(H15=0,"Abandono",IF(H15>=61,"Aprobado","Reprobado")) -> Abandono
C16: 4 | D16: =+'COA-301'!D16:E16 -> 0 | H16: =+F16+G16 -> 0 | J16: =IF(H16=0,"Abandono",IF(H16>=61,"Aprobado","Reprobado")) -> Abandono
C17: 5 | D17: =+'COA-301'!D17:E17 -> 0 | H17: =+F17+G17 -> 0 | J17: =IF(H17=0,"Abandono",IF(H17>=61,"Aprobado","Reprobado")) -> Abandono
C18: 6 | D18: =+'COA-301'!D18:E18 -> 0 | H18: =+F18+G18 -> 0 | J18: =IF(H18=0,"Abandono",IF(H18>=61,"Aprobado","Reprobado")) -> Abandono
C19: 7 | D19: =+'COA-301'!D19:E19 -> 0 | H19: =+F19+G19 -> 0 | J19: =IF(H19=0,"Abandono",IF(H19>=61,"Aprobado","Reprobado")) -> Abandono
C20: 8 | D20: =+'COA-301'!D20:E20 -> 0 | H20: =+F20+G20 -> 0 | J20: =IF(H20=0,"Abandono",IF(H20>=61,"Aprobado","Reprobado")) -> Abandono
C21: 9 | D21: =+'COA-301'!D21:E21 -> 0 | H21: =+F21+G21 -> 0 | J21: =IF(H21=0,"Abandono",IF(H21>=61,"Aprobado","Reprobado")) -> Abandono
C22: 10 | D22: =+'COA-301'!D22:E22 -> 0 | H22: =+F22+G22 -> 0 | J22: =IF(H22=0,"Abandono",IF(H22>=61,"Aprobado","Reprobado")) -> Abandono
C23: 11 | D23: =+'COA-301'!D23:E23 -> 0 | H23: =+F23+G23 -> 0 | J23: =IF(H23=0,"Abandono",IF(H23>=61,"Aprobado","Reprobado")) -> Abandono
C24: 12 | D24: =+'COA-301'!D24:E24 -> 0 | H24: =+F24+G24 -> 0 | J24: =IF(H24=0,"Abandono",IF(H24>=61,"Aprobado","Reprobado")) -> Abandono
... C36: 24 | D36: =+'COA-301'!D36:E36 -> 0 | H36: =+F36+G36 -> 0 | J36: =IF(H36=0,"Abandono",IF(H36>=61,"Aprobado","Reprobado")) -> Abandono
H37: =+F37+G37 -> 0
H38: =+F38+G38 -> 0
H39: =+F39+G39 -> 0
H40: =+F40+G40 -> 0
H41: =+F41+G41 -> 0
H42: =+F42+G42 -> 0
H43: =+F43+G43 -> 0
H44: =+F44+G44 -> 0
H45: =+F45+G45 -> 0
H46: =+F46+G46 -> 0
H47: =+F47+G47 -> 0
G50: RESUMEN | I50: TOTAL | J50: PORCENTAJE
G51: Inscritos | I51: =COUNT(C13:C47) -> 24 | J51: 1
G52: Aprobados | I52: =COUNTIF(J13:K47,"Aprobado") -> 0 | J52: =(I52*J51)/I51 -> 0
G53: Reprobados | I53: =COUNTIF(J13:K47,"Reprobado") -> 0 | J53: =(I53*J51)/I51 -> 0
G54: Abandonos | I54: =COUNTIF(J13:J47,"Abandono") -> 24 | J54: =(I54*J51)/I51 -> 1
B61: Firma y Sello | F61: Sello de la | I61: Firma y Sello
B62: DIRECTOR ACADEMICO | F62: institución | I62: DOCENTE DE LA MATERIA

Sheet CSH-305
A4: INSTITUTO TECNICO DE EDUCACIÓN SUPERIOR "NOVELL"
D5: CARRERA: | E5: CONTADURÍA GENERAL
D6: MENCIÓN:
D7: ÁREA: | E7: COMERCIAL Y SERVICIOS
D8: MATERIA: | E8: CONTABILIDAD DE SERVICIOS (Construcción, Hotelería y Transporte) | I8: SIGLA: | J8: CSH-305
D9: DOCENTE:
D10: AÑO/SEMESTRE: | E10: =+'COA-301'!E10:H10 -> TERCER AÑO | I10: GESTIÓN: | J10: =+'COA-301'!J10:K10 -> 2022
C12: Nro. | D12: Apellidos y Nombres | F12: Prom. Ev. Teórica | G12: Prom. Eval. Práctica | H12: Calificación Final | I12: Prueba de Recuper. | J12: Observación
C13: 1 | D13: =+'COA-301'!D13:E13 -> 0 | H13: =+F13+G13 -> 0 | J13: =IF(H13=0,"Abandono",IF(H13>=61,"Aprobado","Reprobado")) -> Abandono
C14: 2 | D14: =+'COA-301'!D14:E14 -> 0 | H14: =+F14+G14 -> 0 | J14: =IF(H14=0,"Abandono",IF(H14>=61,"Aprobado","Reprobado")) -> Abandono
C15: 3 | D15: =+'COA-301'!D15:E15 -> 0 | H15: =+F15+G15 -> 0 | J15: =IF(H15=0,"Abandono",IF(H15>=61,"Aprobado","Reprobado")) -> Abandono
C16: 4 | D16: =+'COA-301'!D16:E16 -> 0 | H16: =+F16+G16 -> 0 | J16: =IF(H16=0,"Abandono",IF(H16>=61,"Aprobado","Reprobado")) -> Abandono
C17: 5 | D17: =+'COA-301'!D17:E17 -> 0 | H17: =+F17+G17 -> 0 | J17: =IF(H17=0,"Abandono",IF(H17>=61,"Aprobado","Reprobado")) -> Abandono
C18: 6 | D18: =+'COA-301'!D18:E18 -> 0 | H18: =+F18+G18 -> 0 | J18: =IF(H18=0,"Abandono",IF(H18>=61,"Aprobado","Reprobado")) -> Abandono
C19: 7 | D19: =+'COA-301'!D19:E19 -> 0 | H19: =+F19+G19 -> 0 | J19: =IF(H19=0,"Abandono",IF(H19>=61,"Aprobado","Reprobado")) -> Abandono
C20: 8 | D20: =+'COA-301'!D20:E20 -> 0 | H20: =+F20+G20 -> 0 | J20: =IF(H20=0,"Abandono",IF(H20>=61,"Aprobado","Reprobado")) -> Abandono
C21: 9 | D21: =+'COA-301'!D21:E21 -> 0 | H21: =+F21+G21 -> 0 | J21: =IF(H21=0,"Abandono",IF(H21>=61,"Aprobado","Reprobado")) -> Abandono
C22: 10 | D22: =+'COA-301'!D22:E22 -> 0 | H22: =+F22+G22 -> 0 | J22: =IF(H22=0,"Abandono",IF(H22>=61,"Aprobado","Reprobado")) -> Abandono
C23: 11 | D23: =+'COA-301'!D23:E23 -> 0 | H23: =+F23+G23 -> 0 | J23: =IF(H23=0,"Abandono",IF(H23>=61,"Aprobado","Reprobado")) -> Abandono
C24: 12 | D24: =+'COA-301'!D24:E24 -> 0 | H24: =+F24+G24 -> 0 | J24: =IF(H24=0,"Abandono",IF(H24>=61,"Aprobado","Reprobado")) -> Abandono
... C36: 24 | D36: =+'COA-301'!D36:E36 -> 0 | H36: =+F36+G36 -> 0 | J36: =IF(H36=0,"Abandono",IF(H36>=61,"Aprobado","Reprobado")) -> Abandono
H37: =+F37+G37 -> 0
H38: =+F38+G38 -> 0
H39: =+F39+G39 -> 0
H40: =+F40+G40 -> 0
H41: =+F41+G41 -> 0
H42: =+F42+G42 -> 0
H43: =+F43+G43 -> 0
H44: =+F44+G44 -> 0
H45: =+F45+G45 -> 0
H46: =+F46+G46 -> 0
H47: =+F47+G47 -> 0
G50: RESUMEN | I50: TOTAL | J50: PORCENTAJE
G51: Inscritos | I51: =COUNT(C13:C47) -> 24 | J51: 1
G52: Aprobados | I52: =COUNTIF(J13:K47,"Aprobado") -> 0 | J52: =(I52*J51)/I51 -> 0
G53: Reprobados | I53: =COUNTIF(J13:K47,"Reprobado") -> 0 | J53: =(I53*J51)/I51 -> 0
G54: Abandonos | I54: =COUNTIF(J13:J47,"Abandono") -> 24 | J54: =(I54*J51)/I51 -> 1
B61: Firma y Sello | F61: Sello de la | I61: Firma y Sello
B62: DIRECTOR ACADEMICO | F62: institución | I62: DOCENTE DE LA MATERIA

Sheet GCI-306
A4: INSTITUTO TECNICO DE EDUCACIÓN SUPERIOR "NOVELL"
D5: CARRERA: | E5: CONTADURÍA GENERAL
D6: MENCIÓN:
D7: ÁREA: | E7: COMERCIAL Y SERVICIOS
D8: MATERIA: | E8: GABINETE CONTABLE INFORMÁTICO | I8: SIGLA: | J8: GCI-306
D9: DOCENTE:
D10: AÑO/SEMESTRE: | E10: =+'COA-301'!E10:H10 -> TERCER AÑO | I10: GESTIÓN: | J10: =+'COA-301'!J10:K10 -> 2022
C12: Nro. | D12: Apellidos y Nombres | F12: Prom. Ev. Teórica | G12: Prom. Eval. Práctica | H12: Calificación Final | I12: Prueba de Recuper. | J12: Observación
C13: 1 | D13: =+'COA-301'!D13:E13 -> 0 | H13: =+F13+G13 -> 0 | J13: =IF(H13=0,"Abandono",IF(H13>=61,"Aprobado","Reprobado")) -> Abandono
C14: 2 | D14: =+'COA-301'!D14:E14 -> 0 | H14: =+F14+G14 -> 0 | J14: =IF(H14=0,"Abandono",IF(H14>=61,"Aprobado","Reprobado")) -> Abandono
C15: 3 | D15: =+'COA-301'!D15:E15 -> 0 | H15: =+F15+G15 -> 0 | J15: =IF(H15=0,"Abandono",IF(H15>=61,"Aprobado","Reprobado")) -> Abandono
C16: 4 | D16: =+'COA-301'!D16:E16 -> 0 | H16: =+F16+G16 -> 0 | J16: =IF(H16=0,"Abandono",IF(H16>=61,"Aprobado","Reprobado")) -> Abandono
C17: 5 | D17: =+'COA-301'!D17:E17 -> 0 | H17: =+F17+G17 -> 0 | J17: =IF(H17=0,"Abandono",IF(H17>=61,"Aprobado","Reprobado")) -> Abandono
C18: 6 | D18: =+'COA-301'!D18:E18 -> 0 | H18: =+F18+G18 -> 0 | J18: =IF(H18=0,"Abandono",IF(H18>=61,"Aprobado","Reprobado")) -> Abandono
C19: 7 | D19: =+'COA-301'!D19:E19 -> 0 | H19: =+F19+G19 -> 0 | J19: =IF(H19=0,"Abandono",IF(H19>=61,"Aprobado","Reprobado")) -> Abandono
C20: 8 | D20: =+'COA-301'!D20:E20 -> 0 | H20: =+F20+G20 -> 0 | J20: =IF(H20=0,"Abandono",IF(H20>=61,"Aprobado","Reprobado")) -> Abandono
C21: 9 | D21: =+'COA-301'!D21:E21 -> 0 | H21: =+F21+G21 -> 0 | J21: =IF(H21=0,"Abandono",IF(H21>=61,"Aprobado","Reprobado")) -> Abandono
C22: 10 | D22: =+'COA-301'!D22:E22 -> 0 | H22: =+F22+G22 -> 0 | J22: =IF(H22=0,"Abandono",IF(H22>=61,"Aprobado","Reprobado")) -> Abandono
C23: 11 | D23: =+'COA-301'!D23:E23 -> 0 | H23: =+F23+G23 -> 0 | J23: =IF(H23=0,"Abandono",IF(H23>=61,"Aprobado","Reprobado")) -> Abandono
C24: 12 | D24: =+'COA-301'!D24:E24 -> 0 | H24: =+F24+G24 -> 0 | J24: =IF(H24=0,"Abandono",IF(H24>=61,"Aprobado","Reprobado")) -> Abandono
... C36: 24 | D36: =+'COA-301'!D36:E36 -> 0 | H36: =+F36+G36 -> 0 | J36: =IF(H36=0,"Abandono",IF(H36>=61,"Aprobado","Reprobado")) -> Abandono
H37: =+F37+G37 -> 0
H38: =+F38+G38 -> 0
H39: =+F39+G39 -> 0
H40: =+F40+G40 -> 0
H41: =+F41+G41 -> 0
H42: =+F42+G42 -> 0
H43: =+F43+G43 -> 0
H44: =+F44+G44 -> 0
H45: =+F45+G45 -> 0
H46: =+F46+G46 -> 0
H47: =+F47+G47 -> 0
G50: RESUMEN | I50: TOTAL | J50: PORCENTAJE
G51: Inscritos | I51: =COUNT(C13:C47) -> 24 | J51: 1
G52: Aprobados | I52: =COUNTIF(J13:K47,"Aprobado") -> 0 | J52: =(I52*J51)/I51 -> 0
G53: Reprobados | I53: =COUNTIF(J13:K47,"Reprobado") -> 0 | J53: =(I53*J51)/I51 -> 0
G54: Abandonos | I54: =COUNTIF(J13:J47,"Abandono") -> 24 | J54: =(I54*J51)/I51 -> 1
B61: Firma y Sello | F61: Sello de la | I61: Firma y Sello
B62: DIRECTOR ACADEMICO | F62: institución | I62: DOCENTE DE LA MATERIA

Sheet AEF-307
A4: INSTITUTO TECNICO DE EDUCACIÓN SUPERIOR "NOVELL"
D5: CARRERA: | E5: CONTADURÍA GENERAL
D6: MENCIÓN:
D7: ÁREA: | E7: COMERCIAL Y SERVICIOS
D8: MATERIA: | E8: ANÁLISIS E INTERPRETACIONES DE ESTADOS FINANCIEROS | I8: SIGLA: | J8: AEF-307
D9: DOCENTE:
D10: AÑO/SEMESTRE: | E10: =+'COA-301'!E10:H10 -> TERCER AÑO | I10: GESTIÓN: | J10: =+'COA-301'!J10:K10 -> 2022
C12: Nro. | D12: Apellidos y Nombres | F12: Prom. Ev. Teórica | G12: Prom. Eval. Práctica | H12: Calificación Final | I12: Prueba de Recuper. | J12: Observación
C13: 1 | D13: =+'COA-301'!D13:E13 -> 0 | H13: =+F13+G13 -> 0 | J13: =IF(H13=0,"Abandono",IF(H13>=61,"Aprobado","Reprobado")) -> Abandono
C14: 2 | D14: =+'COA-301'!D14:E14 -> 0 | H14: =+F14+G14 -> 0 | J14: =IF(H14=0,"Abandono",IF(H14>=61,"Aprobado","Reprobado")) -> Abandono
C15: 3 | D15: =+'COA-301'!D15:E15 -> 0 | H15: =+F15+G15 -> 0 | J15: =IF(H15=0,"Abandono",IF(H15>=61,"Aprobado","Reprobado")) -> Abandono
C16: 4 | D16: =+'COA-301'!D16:E16 -> 0 | H16: =+F16+G16 -> 0 | J16: =IF(H16=0,"Abandono",IF(H16>=61,"Aprobado","Reprobado")) -> Abandono
C17: 5 | D17: =+'COA-301'!D17:E17 -> 0 | H17: =+F17+G17 -> 0 | J17: =IF(H17=0,"Abandono",IF(H17>=61,"Aprobado","Reprobado")) -> Abandono
C18: 6 | D18: =+'COA-301'!D18:E18 -> 0 | H18: =+F18+G18 -> 0 | J18: =IF(H18=0,"Abandono",IF(H18>=61,"Aprobado","Reprobado")) -> Abandono
C19: 7 | D19: =+'COA-301'!D19:E19 -> 0 | H19: =+F19+G19 -> 0 | J19: =IF(H19=0,"Abandono",IF(H19>=61,"Aprobado","Reprobado")) -> Abandono
C20: 8 | D20: =+'COA-301'!D20:E20 -> 0 | H20: =+F20+G20 -> 0 | J20: =IF(H20=0,"Abandono",IF(H20>=61,"Aprobado","Reprobado")) -> Abandono
C21: 9 | D21: =+'COA-301'!D21:E21 -> 0 | H21: =+F21+G21 -> 0 | J21: =IF(H21=0,"Abandono",IF(H21>=61,"Aprobado","Reprobado")) -> Abandono
C22: 10 | D22: =+'COA-301'!D22:E22 -> 0 | H22: =+F22+G22 -> 0 | J22: =IF(H22=0,"Abandono",IF(H22>=61,"Aprobado","Reprobado")) -> Abandono
C23: 11 | D23: =+'COA-301'!D23:E23 -> 0 | H23: =+F23+G23 -> 0 | J23: =IF(H23=0,"Abandono",IF(H23>=61,"Aprobado","Reprobado")) -> Abandono
C24: 12 | D24: =+'COA-301'!D24:E24 -> 0 | H24: =+F24+G24 -> 0 | J24: =IF(H24=0,"Abandono",IF(H24>=61,"Aprobado","Reprobado")) -> Abandono
... C36: 24 | D36: =+'COA-301'!D36:E36 -> 0 | H36: =+F36+G36 -> 0 | J36: =IF(H36=0,"Abandono",IF(H36>=61,"Aprobado","Reprobado")) -> Abandono
H37: =+F37+G37 -> 0
H38: =+F38+G38 -> 0
H39: =+F39+G39 -> 0
H40: =+F40+G40 -> 0
H41: =+F41+G41 -> 0
H42: =+F42+G42 -> 0
H43: =+F43+G43 -> 0
H44: =+F44+G44 -> 0
H45: =+F45+G45 -> 0
H46: =+F46+G46 -> 0
H47: =+F47+G47 -> 0
G50: RESUMEN | I50: TOTAL | J50: PORCENTAJE
G51: Inscritos | I51: =COUNT(C13:C47) -> 24 | J51: 1
G52: Aprobados | I52: =COUNTIF(J13:K47,"Aprobado") -> 0 | J52: =(I52*J51)/I51 -> 0
G53: Reprobados | I53: =COUNTIF(J13:K47,"Reprobado") -> 0 | J53: =(I53*J51)/I51 -> 0
G54: Abandonos | I54: =COUNTIF(J13:J47,"Abandono") -> 24 | J54: =(I54*J51)/I51 -> 1
B61: Firma y Sello | F61: Sello de la | I61: Firma y Sello
B62: DIRECTOR ACADEMICO | F62: institución | I62: DOCENTE DE LA MATERIA

Sheet TMG-308
A4: INSTITUTO TECNICO DE EDUCACIÓN SUPERIOR "NOVELL"
D5: CARRERA: | E5: CONTADURÍA GENERAL
D6: MENCIÓN:
D7: ÁREA: | E7: COMERCIAL Y SERVICIOS
D8: MATERIA: | E8: TALLER DE MODALIDAD DE GRADUACIÓN | I8: SIGLA: | J8: TMG-308
D9: DOCENTE:
D10: AÑO/SEMESTRE: | E10: =+'COA-301'!E10:H10 -> TERCER AÑO | I10: GESTIÓN: | J10: =+'COA-301'!J10:K10 -> 2022
C12: Nro. | D12: Apellidos y Nombres | F12: Prom. Ev. Teórica | G12: Prom. Eval. Práctica | H12: Calificación Final | I12: Prueba de Recuper. | J12: Observación
C13: 1 | D13: =+'COA-301'!D13:E13 -> 0 | H13: =+F13+G13 -> 0 | J13: =IF(H13=0,"Abandono",IF(H13>=61,"Aprobado","Reprobado")) -> Abandono
C14: 2 | D14: =+'COA-301'!D14:E14 -> 0 | H14: =+F14+G14 -> 0 | J14: =IF(H14=0,"Abandono",IF(H14>=61,"Aprobado","Reprobado")) -> Abandono
C15: 3 | D15: =+'COA-301'!D15:E15 -> 0 | H15: =+F15+G15 -> 0 | J15: =IF(H15=0,"Abandono",IF(H15>=61,"Aprobado","Reprobado")) -> Abandono
C16: 4 | D16: =+'COA-301'!D16:E16 -> 0 | H16: =+F16+G16 -> 0 | J16: =IF(H16=0,"Abandono",IF(H16>=61,"Aprobado","Reprobado")) -> Abandono
C17: 5 | D17: =+'COA-301'!D17:E17 -> 0 | H17: =+F17+G17 -> 0 | J17: =IF(H17=0,"Abandono",IF(H17>=61,"Aprobado","Reprobado")) -> Abandono
C18: 6 | D18: =+'COA-301'!D18:E18 -> 0 | H18: =+F18+G18 -> 0 | J18: =IF(H18=0,"Abandono",IF(H18>=61,"Aprobado","Reprobado")) -> Abandono
C19: 7 | D19: =+'COA-301'!D19:E19 -> 0 | H19: =+F19+G19 -> 0 | J19: =IF(H19=0,"Abandono",IF(H19>=61,"Aprobado","Reprobado")) -> Abandono
C20: 8 | D20: =+'COA-301'!D20:E20 -> 0 | H20: =+F20+G20 -> 0 | J20: =IF(H20=0,"Abandono",IF(H20>=61,"Aprobado","Reprobado")) -> Abandono
C21: 9 | D21: =+'COA-301'!D21:E21 -> 0 | H21: =+F21+G21 -> 0 | J21: =IF(H21=0,"Abandono",IF(H21>=61,"Aprobado","Reprobado")) -> Abandono
C22: 10 | D22: =+'COA-301'!D22:E22 -> 0 | H22: =+F22+G22 -> 0 | J22: =IF(H22=0,"Abandono",IF(H22>=61,"Aprobado","Reprobado")) -> Abandono
C23: 11 | D23: =+'COA-301'!D23:E23 -> 0 | H23: =+F23+G23 -> 0 | J23: =IF(H23=0,"Abandono",IF(H23>=61,"Aprobado","Reprobado")) -> Abandono
C24: 12 | D24: =+'COA-301'!D24:E24 -> 0 | H24: =+F24+G24 -> 0 | J24: =IF(H24=0,"Abandono",IF(H24>=61,"Aprobado","Reprobado")) -> Abandono
... C36: 24 | D36: =+'COA-301'!D36:E36 -> 0 | H36: =+F36+G36 -> 0 | J36: =IF(H36=0,"Abandono",IF(H36>=61,"Aprobado","Reprobado")) -> Abandono
H37: =+F37+G37 -> 0
H38: =+F38+G38 -> 0
H39: =+F39+G39 -> 0
H40: =+F40+G40 -> 0
H41: =+F41+G41 -> 0
H42: =+F42+G42 -> 0
H43: =+F43+G43 -> 0
H44: =+F44+G44 -> 0
H45: =+F45+G45 -> 0
H46: =+F46+G46 -> 0
H47: =+F47+G47 -> 0
G50: RESUMEN | I50: TOTAL | J50: PORCENTAJE
G51: Inscritos | I51: =COUNT(C13:C47) -> 24 | J51: 1
G52: Aprobados | I52: =COUNTIF(J13:K47,"Aprobado") -> 0 | J52: =(I52*J51)/I51 -> 0
G53: Reprobados | I53: =COUNTIF(J13:K47,"Reprobado") -> 0 | J53: =(I53*J51)/I51 -> 0
G54: Abandonos | I54: =COUNTIF(J13:J47,"Abandono") -> 24 | J54: =(I54*J51)/I51 -> 1
B61: Firma y Sello | F61: Sello de la | I61: Firma y Sello
B62: DIRECTOR ACADEMICO | F62: institución | I62: DOCENTE DE LA MATERIA

Sheet Centralizador 3er año Tarde
F3: CENTRALIZADOR DE CALIFICACIONES
S5: TURNO: | U5: TARDE
C6: INSTITUCIÓN: | E6: INSTITUTO TECNICO DE EDUCACIÓN SUPERIOR "NOVELL" | Q6: R.M. | R6: 0906/02 | S6: CARÁCTER: | U6: PRIVADO
C7: GESTIÓN ACADÉMICA: | E7: 2022 | F7: CÉDULA DE IDENTIDAD | G7: COA-301 | H7: COC-302 | I7: COG-303 | J7: CEP-304 | K7: CSH-305 | L7: GCI-306 | M7: AEF-307 | N7: TMG-308 | V7: OBSERVACIONES
G8: CONTABILIDAD AGROPECUARIA | H8: CONTABILIDAD DE COSTOS II | I8: CONTABILIDAD GUBERNAMENTAL | J8: CONTABILIDAD EXTRACTIVA (MINERA, PETROLERA Y FORESTAL) | K8: CONTABILIDAD DE SERVICIOS (CONSTRUCCIÓN, HOTELERÍA Y TRANSPORTE) | L8: GABINETA CONTABLE INFORMÁTICO | M8: ANÁLISIS E INTERPRETACIONES DE ESTADOS FINANCIEROS | N8: TALLER DE MODALIDAD DE GRADUACIÓN
C9: NIVEL: | E9: TECNICO SUPERIOR
C10: CARRERA: | E10: CONTADURIA GENERAL
C11: RÉGIMEN: | E11: ANUAL
C12: CURSO: | E12: TERCER AÑO - A
C13: N° | D13: NÓMINA ESTUDIANTES
C14: 1 | D14: =+'COA-301 T'!D13:E13 -> Choque Choque Eneida | F14: 4078247 Or. | G14: =+'COA-301 T'!H13 -> 0 | H14: =+'COC-302 T'!H13 -> 0 | I14: =+'COG-303 T'!H13 -> 0 | J14: =+'CEP-304 T'!H13 -> 0 | K14: =+'CSH-305 T'!H13 -> 0 | L14: =+'GCI-306 T'!H13 -> 0 | M14: =+'AEF-307 T'!H13 -> 0 | N14: =+'TMG-308 T'!H13 -> 0 | V14: =IF(M14=0,"Abandono",IF(AVERAGE(G14:M14)>=61,"Aprobado","Reprobado")) -> Abandono
C15: 2 | D15: =+'COA-301 T'!D14:E14 -> Condori Felipez Nahely | F15: 7405160 Or. | G15: =+'COA-301 T'!H14 -> 0 | H15: =+'COC-302 T'!H14 -> 0 | I15: =+'COG-303 T'!H14 -> 0 | J15: =+'CEP-304 T'!H14 -> 0 | K15: =+'CSH-305 T'!H14 -> 0 | L15: =+'GCI-306 T'!H14 -> 0 | M15: =+'AEF-307 T'!H14 -> 0 | N15: =+'TMG-308 T'!H14 -> 0 | V15: =IF(M15=0,"Abandono",IF(AVERAGE(G15:M15)>=61,"Aprobado","Reprobado")) -> Abandono
C16: 3 | D16: =+'COA-301 T'!D15:E15 -> Cusi Cruz Ramiro | F16: 4299411 Lp. | G16: =+'COA-301 T'!H15 -> 0 | H16: =+'COC-302 T'!H15 -> 0 | I16: =+'COG-303 T'!H15 -> 0 | J16: =+'CEP-304 T'!H15 -> 0 | K16: =+'CSH-305 T'!H15 -> 0 | L16: =+'GCI-306 T'!H15 -> 0 | M16: =+'AEF-307 T'!H15 -> 0 | N16: =+'TMG-308 T'!H15 -> 0 | V16: =IF(M16=0,"Abandono",IF(AVERAGE(G16:M16)>=61,"Aprobado","Reprobado")) -> Abandono
C17: 4 | D17: =+'COA-301 T'!D16:E16 -> Diaz Soruco Milenka Ingrid | F17: 6712229 | G17: =+'COA-301 T'!H16 -> 80 | H17: =+'COC-302 T'!H16 -> 91 | I17: =+'COG-303 T'!H16 -> 78 | J17: =+'CEP-304 T'!H16 -> 94 | K17: =+'CSH-305 T'!H16 -> 81 | L17: =+'GCI-306 T'!H16 -> 84 | M17: =+'AEF-307 T'!H16 -> 80 | N17: =+'TMG-308 T'!H16 -> 84 | V17: =IF(M17=0,"Abandono",IF(AVERAGE(G17:M17)>=61,"Aprobado","Reprobado")) -> Aprobado
C18: 5 | D18: =+'COA-301 T'!D17:E17 -> Fernandez Choque Karen Carolina | F18: 7412669 Or. | G18: =+'COA-301 T'!H17 -> 90 | H18: =+'COC-302 T'!H17 -> 88 | I18: =+'COG-303 T'!H17 -> 90 | J18: =+'CEP-304 T'!H17 -> 92 | K18: =+'CSH-305 T'!H17 -> 87 | L18: =+'GCI-306 T'!H17 -> 93 | M18: =+'AEF-307 T'!H17 -> 90 | N18: =+'TMG-308 T'!H17 -> 92 | V18: =IF(M18=0,"Abandono",IF(AVERAGE(G18:M18)>=61,"Aprobado","Reprobado")) -> Aprobado
C19: 6 | D19: =+'COA-301 T'!D18:E18 -> Flores Condarco Eberth Luis | F19: 5737660 Or. | G19: =+'COA-301 T'!H18 -> 63 | H19: =+'COC-302 T'!H18 -> 62 | I19: =+'COG-303 T'!H18 -> 62 | J19: =+'CEP-304 T'!H18 -> 65 | K19: =+'CSH-305 T'!H18 -> 66 | L19: =+'GCI-306 T'!H18 -> 66 | M19: =+'AEF-307 T'!H18 -> 61 | N19: =+'TMG-308 T'!H18 -> 65 | V19: =IF(M19=0,"Abandono",IF(AVERAGE(G19:M19)>=61,"Aprobado","Reprobado")) -> Aprobado
C20: 7 | D20: =+'COA-301 T'!D19:E19 -> Guarachi Bolivar Ariel Leonel | F20: 7335226 | G20: =+'COA-301 T'!H19 -> 0 | H20: =+'COC-302 T'!H19 -> 0 | I20: =+'COG-303 T'!H19 -> 0 | J20: =+'CEP-304 T'!H19 -> 0 | K20: =+'CSH-305 T'!H19 -> 0 | L20: =+'GCI-306 T'!H19 -> 0 | M20: =+'AEF-307 T'!H19 -> 0 | N20: =+'TMG-308 T'!H19 -> 0 | V20: =IF(M20=0,"Abandono",IF(AVERAGE(G20:M20)>=61,"Aprobado","Reprobado")) -> Abandono
C21: 8 | D21: =+'COA-301 T'!D20:E20 -> Guarachi Bolivar Omar Rodrigo | F21: 4038174 Or. | G21: =+'COA-301 T'!H20 -> 0 | H21: =+'COC-302 T'!H20 -> 0 | I21: =+'COG-303 T'!H20 -> 0 | J21: =+'CEP-304 T'!H20 -> 0 | K21: =+'CSH-305 T'!H20 -> 0 | L21: =+'GCI-306 T'!H20 -> 0 | M21: =+'AEF-307 T'!H20 -> 0 | N21: =+'TMG-308 T'!H20 -> 0 | V21: =IF(M21=0,"Abandono",IF(AVERAGE(G21:M21)>=61,"Aprobado","Reprobado")) -> Abandono
C22: 9 | D22: =+'COA-301 T'!D21:E21 -> Lazarte Escobar Cristian Fernando | F22: 4062507 Or. | G22: =+'COA-301 T'!H21 -> 0 | H22: =+'COC-302 T'!H21 -> 0 | I22: =+'COG-303 T'!H21 -> 0 | J22: =+'CEP-304 T'!H21 -> 0 | K22: =+'CSH-305 T'!H21 -> 0 | L22: =+'GCI-306 T'!H21 -> 0 | M22: =+'AEF-307 T'!H21 -> 0 | N22: =+'TMG-308 T'!H21 -> 0 | V22: =IF(M22=0,"Abandono",IF(AVERAGE(G22:M22)>=61,"Aprobado","Reprobado")) -> Abandono
C23: 10 | D23: =+'COA-301 T'!D22:E22 -> Manzano Huanca David Hernan | F23: 7334651 Or. | G23: =+'COA-301 T'!H22 -> 94 | H23: =+'COC-302 T'!H22 -> 95 | I23: =+'COG-303 T'!H22 -> 100 | J23: =+'CEP-304 T'!H22 -> 84 | K23: =+'CSH-305 T'!H22 -> 92 | L23: =+'GCI-306 T'!H22 -> 100 | M23: =+'AEF-307 T'!H22 -> 93 | N23: =+'TMG-308 T'!H22 -> 98 | V23: =IF(M23=0,"Abandono",IF(AVERAGE(G23:M23)>=61,"Aprobado","Reprobado")) -> Aprobado
C24: 11 | D24: =+'COA-301 T'!D23:E23 -> Salinas Lopez Elvis Alex | F24: 7386227 Or. | G24: =+'COA-301 T'!H23 -> 85 | H24: =+'COC-302 T'!H23 -> 83 | I24: =+'COG-303 T'!H23 -> 85 | J24: =+'CEP-304 T'!H23 -> 87 | K24: =+'CSH-305 T'!H23 -> 81 | L24: =+'GCI-306 T'!H23 -> 88 | M24: =+'AEF-307 T'!H23 -> 85 | N24: =+'TMG-308 T'!H23 -> 83 | V24: =IF(M24=0,"Abandono",IF(AVERAGE(G24:M24)>=61,"Aprobado","Reprobado")) -> Aprobado
C25: 12 | D25: =+'COA-301 T'!D24:E24 -> Tellez Ledo Axel Jairo | F25: 7290846 Or. | G25: 61 | H25: =+'COC-302 T'!H24 -> 69 | I25: 61 | J25: =+'CEP-304 T'!H24 -> 73 | K25: =+'CSH-305 T'!H24 -> 70 | L25: =+'GCI-306 T'!H24 -> 66 | M25: 61 | N25: =+'TMG-308 T'!H24 -> 68 | V25: =IF(M25=0,"Abandono",IF(AVERAGE(G25:M25)>=61,"Aprobado","Reprobado")) -> Aprobado
C44: *En observaciones tomar en cuenta: Aprobado, Reprobado y Abandono
E48: Firma y Sello | H48: Sello de la | K48: Firma y Sello
E49: DIRECTOR ACADEMICO | H49: institución | K49: Vo.Bo. RECTOR
O50: ELABORADO POR:
O51: NOMBRE: | Q51: T.S. DAYANA VIRREIRA CANO
O52: CARGO: | Q52: SECRETARIA EJECUTIVA
D53: DETALLE | G53: CANTIDAD | H53: PORCENT. | O53: FIRMA:
D54: ESTUDIANTES INSCRITOS | G54: =COUNT(C14:C41) -> 12 | H54: 1 | O54: FECHA: | Q54: ORURO, 25 DE NOVIEMBRE DE 2022
D55: ESTUDIANTES APROBADOS | G55: =COUNTIF(V14:V43,"Aprobado") -> 6 | H55: =(G55*H54)/G54 -> 0.5
D56: ESTUDIANTES REPROBADOS | G56: =COUNTIF(V14:V43,"Reprobado") -> 0 | H56: =(G56*H54)/G54 -> 0
D57: ABADONO | G57: =COUNTIF(V14:V43,"Abandono") -> 6 | H57: =(G57*H54)/G54 -> 0.5

Sheet COA-301 T
A4: INSTITUTO TECNICO DE EDUCACIÓN SUPERIOR "NOVELL"
D5: CARRERA: | E5: CONTADURÍA GENERAL
D6: MENCIÓN:
D7: ÁREA: | E7: COMERCIAL Y SERVICIOS
D8: MATERIA: | E8: =+'COA-301'!E8:H8 -> CONTABILIDAD AGROPECUARIA | I8: SIGLA: | J8: =+'COA-301'!J8:K8 -> COA-301
D9: DOCENTE: | E9: LIC. MARIA ELENA MAMANI MACEDA
D10: AÑO/SEMESTRE: | E10: =+'COA-301'!E10:H10 -> TERCER AÑO | I10: GESTIÓN: | J10: =+'COA-301'!J10:K10 -> 2022
C12: Nro. | D12: Apellidos y Nombres | F12: Prom. Ev. Teórica | G12: Prom. Eval. Práctica | H12: Calificación Final | I12: Prueba de Recuper. | J12: Observación
C13: 1 | D13: Choque Choque Eneida | F13: 0 | G13: 0 | H13: =F13+G13 -> 0 | J13: =IF(H13=0,"Abandono",IF(OR(H13>=61,I13=61),"Aprobado","Reprobado")) -> Abandono
C14: 2 | D14: Condori Felipez Nahely | F14: 0 | G14: 0 | H14: =F14+G14 -> 0 | J14: =IF(H14=0,"Abandono",IF(OR(H14>=61,I14=61),"Aprobado","Reprobado")) -> Abandono
C15: 3 | D15: Cusi Cruz Ramiro | F15: 0 | G15: 0 | H15: =F15+G15 -> 0 | J15: =IF(H15=0,"Abandono",IF(OR(H15>=61,I15=61),"Aprobado","Reprobado")) -> Abandono
C16: 4 | D16: Diaz Soruco Milenka Ingrid | F16: 20 | G16: 60 | H16: =F16+G16 -> 80 | J16: =IF(H16=0,"Abandono",IF(OR(H16>=61,I16=61),"Aprobado","Reprobado")) -> Aprobado
C17: 5 | D17: Fernandez Choque Karen Carolina | F17: 30 | G17: 60 | H17: =F17+G17 -> 90 | J17: =IF(H17=0,"Abandono",IF(OR(H17>=61,I17=61),"Aprobado","Reprobado")) -> Aprobado
C18: 6 | D18: Flores Condarco Eberth Luis | F18: 18 | G18: 45 | H18: =F18+G18 -> 63 | J18: =IF(H18=0,"Abandono",IF(OR(H18>=61,I18=61),"Aprobado","Reprobado")) -> Aprobado
C19: 7 | D19: Guarachi Bolivar Ariel Leonel | F19: 0 | G19: 0 | H19: =F19+G19 -> 0 | J19: =IF(H19=0,"Abandono",IF(OR(H19>=61,I19=61),"Aprobado","Reprobado")) -> Abandono
C20: 8 | D20: Guarachi Bolivar Omar Rodrigo | F20: 0 | G20: 0 | H20: =F20+G20 -> 0 | J20: =IF(H20=0,"Abandono",IF(OR(H20>=61,I20=61),"Aprobado","Reprobado")) -> Abandono
C21: 9 | D21: Lazarte Escobar Cristian Fernando | F21: 0 | G21: 0 | H21: =F21+G21 -> 0 | J21: =IF(H21=0,"Abandono",IF(OR(H21>=61,I21=61),"Aprobado","Reprobado")) -> Abandono
C22: 10 | D22: Manzano Huanca David Hernan | F22: 27 | G22: 67 | H22: =F22+G22 -> 94 | J22: =IF(H22=0,"Abandono",IF(OR(H22>=61,I22=61),"Aprobado","Reprobado")) -> Aprobado
C23: 11 | D23: Salinas Lopez Elvis Alex | F23: 30 | G23: 55 | H23: =F23+G23 -> 85 | J23: =IF(H23=0,"Abandono",IF(OR(H23>=61,I23=61),"Aprobado","Reprobado")) -> Aprobado
C24: 12 | D24: Tellez Ledo Axel Jairo | F24: 10 | G24: 35 | H24: =F24+G24 -> 45 | I24: 61 | J24: =IF(H24=0,"Abandono",IF(OR(H24>=61,I24=61),"Aprobado","Reprobado")) -> Aprobado
G50: RESUMEN | I50: TOTAL | J50: PORCENTAJE
G51: Inscritos | I51: =COUNT(C13:C47) -> 12 | J51: 1
G52: Aprobados | I52: =COUNTIF(J13:K47,"Aprobado") -> 6 | J52: =(I52*J51)/I51 -> 0.5
G53: Reprobados | I53: =COUNTIF(J13:K47,"Reprobado") -> 0 | J53: =(I53*J51)/I51 -> 0
G54: Abandonos | I54: =COUNTIF(J13:J47,"Abandono") -> 6 | J54: =(I54*J51)/I51 -> 0.5
B61: Firma y Sello | F61: Sello de la | I61: Firma y Sello
B62: DIRECTOR ACADEMICO | F62: institución | I62: DOCENTE DE LA MATERIA

Sheet COC-302 T
A4: INSTITUTO TECNICO DE EDUCACIÓN SUPERIOR "NOVELL"
D5: CARRERA: | E5: CONTADURÍA GENERAL
D6: MENCIÓN:
D7: ÁREA: | E7: COMERCIAL Y SERVICIOS
D8: MATERIA: | E8: =+'COC-302'!E8:H8 -> CONTABILIDAD DE COSTOS II | I8: SIGLA: | J8: =+'COC-302'!J8:K8 -> COC-302
D9: DOCENTE: | E9: LIC. WILSON PEÑAFIEL SEJAS
D10: AÑO/SEMESTRE: | E10: =+'COA-301'!E10:H10 -> TERCER AÑO | I10: GESTIÓN: | J10: =+'COA-301'!J10:K10 -> 2022
C12: Nro. | D12: Apellidos y Nombres | F12: Prom. Ev. Teórica | G12: Prom. Eval. Práctica | H12: Calificación Final | I12: Prueba de Recuper. | J12: Observación
C13: 1 | D13: =+'COA-301 T'!D13:E13 -> Choque Choque Eneida | F13: 0 | G13: 0 | H13: =+F13+G13 -> 0 | J13: =IF(H13=0,"Abandono",IF(OR(H13>=61,I13=61),"Aprobado","Reprobado")) -> Abandono
C14: 2 | D14: =+'COA-301 T'!D14:E14 -> Condori Felipez Nahely | F14: 0 | G14: 0 | H14: =+F14+G14 -> 0 | J14: =IF(H14=0,"Abandono",IF(OR(H14>=61,I14=61),"Aprobado","Reprobado")) -> Abandono
C15: 3 | D15: =+'COA-301 T'!D15:E15 -> Cusi Cruz Ramiro | F15: 0 | G15: 0 | H15: =+F15+G15 -> 0 | J15: =IF(H15=0,"Abandono",IF(OR(H15>=61,I15=61),"Aprobado","Reprobado")) -> Abandono
C16: 4 | D16: =+'COA-301 T'!D16:E16 -> Diaz Soruco Milenka Ingrid | F16: 28 | G16: 63 | H16: =+F16+G16 -> 91 | J16: =IF(H16=0,"Abandono",IF(OR(H16>=61,I16=61),"Aprobado","Reprobado")) -> Aprobado
C17: 5 | D17: =+'COA-301 T'!D17:E17 -> Fernandez Choque Karen Carolina | F17: 28 | G17: 60 | H17: =+F17+G17 -> 88 | J17: =IF(H17=0,"Abandono",IF(OR(H17>=61,I17=61),"Aprobado","Reprobado")) -> Aprobado
C18: 6 | D18: =+'COA-301 T'!D18:E18 -> Flores Condarco Eberth Luis | F18: 20 | G18: 42 | H18: =+F18+G18 -> 62 | J18: =IF(H18=0,"Abandono",IF(OR(H18>=61,I18=61),"Aprobado","Reprobado")) -> Aprobado
C19: 7 | D19: =+'COA-301 T'!D19:E19 -> Guarachi Bolivar Ariel Leonel | F19: 0 | G19: 0 | H19: =+F19+G19 -> 0 | J19: =IF(H19=0,"Abandono",IF(OR(H19>=61,I19=61),"Aprobado","Reprobado")) -> Abandono
C20: 8 | D20: =+'COA-301 T'!D20:E20 -> Guarachi Bolivar Omar Rodrigo | F20: 0 | G20: 0 | H20: =+F20+G20 -> 0 | J20: =IF(H20=0,"Abandono",IF(OR(H20>=61,I20=61),"Aprobado","Reprobado")) -> Abandono
C21: 9 | D21: =+'COA-301 T'!D21:E21 -> Lazarte Escobar Cristian Fernando | F21: 0 | G21: 0 | H21: =+F21+G21 -> 0 | J21: =IF(H21=0,"Abandono",IF(OR(H21>=61,I21=61),"Aprobado","Reprobado")) -> Abandono
C22: 10 | D22: =+'COA-301 T'!D22:E22 -> Manzano Huanca David Hernan | F22: 28 | G22: 67 | H22: =+F22+G22 -> 95 | J22: =IF(H22=0,"Abandono",IF(OR(H22>=61,I22=61),"Aprobado","Reprobado")) -> Aprobado
C23: 11 | D23: =+'COA-301 T'!D23:E23 -> Salinas Lopez Elvis Alex | F23: 30 | G23: 53 | H23: =+F23+G23 -> 83 | J23: =IF(H23=0,"Abandono",IF(OR(H23>=61,I23=61),"Aprobado","Reprobado")) -> Aprobado
C24: 12 | D24: =+'COA-301 T'!D24:E24 -> Tellez Ledo Axel Jairo | F24: 21 | G24: 48 | H24: =+F24+G24 -> 69 | J24: =IF(H24=0,"Abandono",IF(OR(H24>=61,I24=61),"Aprobado","Reprobado")) -> Aprobado
G50: RESUMEN | I50: TOTAL | J50: PORCENTAJE
G51: Inscritos | I51: =COUNT(C13:C47) -> 12 | J51: 1
G52: Aprobados | I52: =COUNTIF(J13:K47,"Aprobado") -> 6 | J52: =(I52*J51)/I51 -> 0.5
G53: Reprobados | I53: =COUNTIF(J13:K47,"Reprobado") -> 0 | J53: =(I53*J51)/I51 -> 0
G54: Abandonos | I54: =COUNTIF(J13:J47,"Abandono") -> 6 | J54: =(I54*J51)/I51 -> 0.5
B61: Firma y Sello | F61: Sello de la | I61: Firma y Sello
B62: DIRECTOR ACADEMICO | F62: institución | I62: DOCENTE DE LA MATERIA

Sheet COG-303 T
A4: INSTITUTO TECNICO DE EDUCACIÓN SUPERIOR "NOVELL"
D5: CARRERA: | E5: CONTADURÍA GENERAL
D6: MENCIÓN:
D7: ÁREA: | E7: COMERCIAL Y SERVICIOS
D8: MATERIA: | E8: =+'COG-303'!E8:H8 -> CONTABILIDAD GUBERNAMENTAL | I8: SIGLA: | J8: =+'COG-303'!J8:K8 -> COG-303
D9: DOCENTE: | E9: LIC. DIVAR AURELIO CRUZ LOPEZ
D10: AÑO/SEMESTRE: | E10: =+'COA-301'!E10:H10 -> TERCER AÑO | I10: GESTIÓN: | J10: =+'COA-301'!J10:K10 -> 2022
C12: Nro. | D12: Apellidos y Nombres | F12: Prom. Ev. Teórica | G12: Prom. Eval. Práctica | H12: Calificación Final | I12: Prueba de Recuper. | J12: Observación
C13: 1 | D13: =+'COA-301 T'!D13:E13 -> Choque Choque Eneida | F13: 0 | G13: 0 | H13: =+F13+G13 -> 0 | J13: =IF(H13=0,"Abandono",IF(OR(H13>=61,I13=61),"Aprobado","Reprobado")) -> Abandono
C14: 2 | D14: =+'COA-301 T'!D14:E14 -> Condori Felipez Nahely | F14: 0 | G14: 0 | H14: =+F14+G14 -> 0 | J14: =IF(H14=0,"Abandono",IF(OR(H14>=61,I14=61),"Aprobado","Reprobado")) -> Abandono
C15: 3 | D15: =+'COA-301 T'!D15:E15 -> Cusi Cruz Ramiro | F15: 0 | G15: 0 | H15: =+F15+G15 -> 0 | J15: =IF(H15=0,"Abandono",IF(OR(H15>=61,I15=61),"Aprobado","Reprobado")) -> Abandono
C16: 4 | D16: =+'COA-301 T'!D16:E16 -> Diaz Soruco Milenka Ingrid | F16: 25 | G16: 53 | H16: =+F16+G16 -> 78 | J16: =IF(H16=0,"Abandono",IF(OR(H16>=61,I16=61),"Aprobado","Reprobado")) -> Aprobado
C17: 5 | D17: =+'COA-301 T'!D17:E17 -> Fernandez Choque Karen Carolina | F17: 30 | G17: 60 | H17: =+F17+G17 -> 90 | J17: =IF(H17=0,"Abandono",IF(OR(H17>=61,I17=61),"Aprobado","Reprobado")) -> Aprobado
C18: 6 | D18: =+'COA-301 T'!D18:E18 -> Flores Condarco Eberth Luis | F18: 21 | G18: 41 | H18: =+F18+G18 -> 62 | J18: =IF(H18=0,"Abandono",IF(OR(H18>=61,I18=61),"Aprobado","Reprobado")) -> Aprobado
C19: 7 | D19: =+'COA-301 T'!D19:E19 -> Guarachi Bolivar Ariel Leonel | F19: 0 | G19: 0 | H19: =+F19+G19 -> 0 | J19: =IF(H19=0,"Abandono",IF(OR(H19>=61,I19=61),"Aprobado","Reprobado")) -> Abandono
C20: 8 | D20: =+'COA-301 T'!D20:E20 -> Guarachi Bolivar Omar Rodrigo | F20: 0 | G20: 0 | H20: =+F20+G20 -> 0 | J20: =IF(H20=0,"Abandono",IF(OR(H20>=61,I20=61),"Aprobado","Reprobado")) -> Abandono
C21: 9 | D21: =+'COA-301 T'!D21:E21 -> Lazarte Escobar Cristian Fernando | F21: 0 | G21: 0 | H21: =+F21+G21 -> 0 | J21: =IF(H21=0,"Abandono",IF(OR(H21>=61,I21=61),"Aprobado","Reprobado")) -> Abandono
C22: 10 | D22: =+'COA-301 T'!D22:E22 -> Manzano Huanca David Hernan | F22: 30 | G22: 70 | H22: =+F22+G22 -> 100 | J22: =IF(H22=0,"Abandono",IF(OR(H22>=61,I22=61),"Aprobado","Reprobado")) -> Aprobado
C23: 11 | D23: =+'COA-301 T'!D23:E23 -> Salinas Lopez Elvis Alex | F23: 30 | G23: 55 | H23: =+F23+G23 -> 85 | J23: =IF(H23=0,"Abandono",IF(OR(H23>=61,I23=61),"Aprobado","Reprobado")) -> Aprobado
C24: 12 | D24: =+'COA-301 T'!D24:E24 -> Tellez Ledo Axel Jairo | F24: 19 | G24: 35 | H24: =+F24+G24 -> 54 | I24: 61 | J24: =IF(H24=0,"Abandono",IF(OR(H24>=61,I24=61),"Aprobado","Reprobado")) -> Aprobado
G50: RESUMEN | I50: TOTAL | J50: PORCENTAJE
G51: Inscritos | I51: =COUNT(C13:C47) -> 12 | J51: 1
G52: Aprobados | I52: =COUNTIF(J13:K47,"Aprobado") -> 6 | J52: =(I52*J51)/I51 -> 0.5
G53: Reprobados | I53: =COUNTIF(J13:K47,"Reprobado") -> 0 | J53: =(I53*J51)/I51 -> 0
G54: Abandonos | I54: =COUNTIF(J13:J47,"Abandono") -> 6 | J54: =(I54*J51)/I51 -> 0.5
B61: Firma y Sello | F61: Sello de la | I61: Firma y Sello
B62: DIRECTOR ACADEMICO | F62: institución | I62: DOCENTE DE LA MATERIA

Sheet CEP-304 T
A4: INSTITUTO TECNICO DE EDUCACIÓN SUPERIOR "NOVELL"
D5: CARRERA: | E5: CONTADURÍA GENERAL
D6: MENCIÓN:
D7: ÁREA: | E7: COMERCIAL Y SERVICIOS
D8: MATERIA: | E8: =+'CEP.304'!E8:H8 -> CONTABILIDAD EXTRACTIVA (Minera, Petrolera y Forestal) | I8: SIGLA: | J8: =+'CEP.304'!J8:K8 -> CEP-304
D9: DOCENTE: | E9: LIC. WILSON PEÑAFIEL SEJAS
D10: AÑO/SEMESTRE: | E10: =+'COA-301'!E10:H10 -> TERCER AÑO | I10: GESTIÓN: | J10: =+'COA-301'!J10:K10 -> 2022
C12: Nro. | D12: Apellidos y Nombres | F12: Prom. Ev. Teórica | G12: Prom. Eval. Práctica | H12: Calificación Final | I12: Prueba de Recuper. | J12: Observación
C13: 1 | D13: =+'COA-301 T'!D13:E13 -> Choque Choque Eneida | F13: 0 | G13: 0 | H13: =+F13+G13 -> 0 | J13: =IF(H13=0,"Abandono",IF(OR(H13>=61,I13=61),"Aprobado","Reprobado")) -> Abandono
C14: 2 | D14: =+'COA-301 T'!D14:E14 -> Condori Felipez Nahely | F14: 0 | G14: 0 | H14: =+F14+G14 -> 0 | J14: =IF(H14=0,"Abandono",IF(OR(H14>=61,I14=61),"Aprobado","Reprobado")) -> Abandono
C15: 3 | D15: =+'COA-301 T'!D15:E15 -> Cusi Cruz Ramiro | F15: 0 | G15: 0 | H15: =+F15+G15 -> 0 | J15: =IF(H15=0,"Abandono",IF(OR(H15>=61,I15=61),"Aprobado","Reprobado")) -> Abandono
C16: 4 | D16: =+'COA-301 T'!D16:E16 -> Diaz Soruco Milenka Ingrid | F16: 27 | G16: 67 | H16: =+F16+G16 -> 94 | J16: =IF(H16=0,"Abandono",IF(OR(H16>=61,I16=61),"Aprobado","Reprobado")) -> Aprobado
C17: 5 | D17: =+'COA-301 T'!D17:E17 -> Fernandez Choque Karen Carolina | F17: 30 | G17: 62 | H17: =+F17+G17 -> 92 | J17: =IF(H17=0,"Abandono",IF(OR(H17>=61,I17=61),"Aprobado","Reprobado")) -> Aprobado
C18: 6 | D18: =+'COA-301 T'!D18:E18 -> Flores Condarco Eberth Luis | F18: 22 | G18: 43 | H18: =+F18+G18 -> 65 | J18: =IF(H18=0,"Abandono",IF(OR(H18>=61,I18=61),"Aprobado","Reprobado")) -> Aprobado
C19: 7 | D19: =+'COA-301 T'!D19:E19 -> Guarachi Bolivar Ariel Leonel | F19: 0 | G19: 0 | H19: =+F19+G19 -> 0 | J19: =IF(H19=0,"Abandono",IF(OR(H19>=61,I19=61),"Aprobado","Reprobado")) -> Abandono
C20: 8 | D20: =+'COA-301 T'!D20:E20 -> Guarachi Bolivar Omar Rodrigo | F20: 0 | G20: 0 | H20: =+F20+G20 -> 0 | J20: =IF(H20=0,"Abandono",IF(OR(H20>=61,I20=61),"Aprobado","Reprobado")) -> Abandono
C21: 9 | D21: =+'COA-301 T'!D21:E21 -> Lazarte Escobar Cristian Fernando | F21: 0 | G21: 0 | H21: =+F21+G21 -> 0 | J21: =IF(H21=0,"Abandono",IF(OR(H21>=61,I21=61),"Aprobado","Reprobado")) -> Abandono
C22: 10 | D22: =+'COA-301 T'!D22:E22 -> Manzano Huanca David Hernan | F22: 25 | G22: 59 | H22: =+F22+G22 -> 84 | J22: =IF(H22=0,"Abandono",IF(OR(H22>=61,I22=61),"Aprobado","Reprobado")) -> Aprobado
C23: 11 | D23: =+'COA-301 T'!D23:E23 -> Salinas Lopez Elvis Alex | F23: 30 | G23: 57 | H23: =+F23+G23 -> 87 | J23: =IF(H23=0,"Abandono",IF(OR(H23>=61,I23=61),"Aprobado","Reprobado")) -> Aprobado
C24: 12 | D24: =+'COA-301 T'!D24:E24 -> Tellez Ledo Axel Jairo | F24: 22 | G24: 51 | H24: =+F24+G24 -> 73 | J24: =IF(H24=0,"Abandono",IF(OR(H24>=61,I24=61),"Aprobado","Reprobado")) -> Aprobado
G50: RESUMEN | I50: TOTAL | J50: PORCENTAJE
G51: Inscritos | I51: =COUNT(C13:C47) -> 12 | J51: 1
G52: Aprobados | I52: =COUNTIF(J13:K47,"Aprobado") -> 6 | J52: =(I52*J51)/I51 -> 0.5
G53: Reprobados | I53: =COUNTIF(J13:K47,"Reprobado") -> 0 | J53: =(I53*J51)/I51 -> 0
G54: Abandonos | I54: =COUNTIF(J13:J47,"Abandono") -> 6 | J54: =(I54*J51)/I51 -> 0.5
B61: Firma y Sello | F61: Sello de la | I61: Firma y Sello
B62: DIRECTOR ACADEMICO | F62: institución | I62: DOCENTE DE LA MATERIA

Sheet CSH-305 T
A4: INSTITUTO TECNICO DE EDUCACIÓN SUPERIOR "NOVELL"
D5: CARRERA: | E5: CONTADURÍA GENERAL
D6: MENCIÓN:
D7: ÁREA: | E7: COMERCIAL Y SERVICIOS
D8: MATERIA: | E8: =+'CSH-305'!E8:H8 -> CONTABILIDAD DE SERVICIOS (Construcción, Hotelería y Transporte) | I8: SIGLA: | J8: =+'CSH-305'!J8:K8 -> CSH-305
D9: DOCENTE: | E9: LIC. DIVAR AURELIO CRUZ LOPEZ
D10: AÑO/SEMESTRE: | E10: =+'COA-301'!E10:H10 -> TERCER AÑO | I10: GESTIÓN: | J10: =+'COA-301'!J10:K10 -> 2022
C12: Nro. | D12: Apellidos y Nombres | F12: Prom. Ev. Teórica | G12: Prom. Eval. Práctica | H12: Calificación Final | I12: Prueba de Recuper. | J12: Observación
C13: 1 | D13: =+'COA-301 T'!D13:E13 -> Choque Choque Eneida | F13: 0 | G13: 0 | H13: =+F13+G13 -> 0 | J13: =IF(H13=0,"Abandono",IF(OR(H13>=61,I13=61),"Aprobado","Reprobado")) -> Abandono
C14: 2 | D14: =+'COA-301 T'!D14:E14 -> Condori Felipez Nahely | F14: 0 | G14: 0 | H14: =+F14+G14 -> 0 | J14: =IF(H14=0,"Abandono",IF(OR(H14>=61,I14=61),"Aprobado","Reprobado")) -> Abandono
C15: 3 | D15: =+'COA-301 T'!D15:E15 -> Cusi Cruz Ramiro | F15: 0 | G15: 0 | H15: =+F15+G15 -> 0 | J15: =IF(H15=0,"Abandono",IF(OR(H15>=61,I15=61),"Aprobado","Reprobado")) -> Abandono
C16: 4 | D16: =+'COA-301 T'!D16:E16 -> Diaz Soruco Milenka Ingrid | F16: 16 | G16: 65 | H16: =+F16+G16 -> 81 | J16: =IF(H16=0,"Abandono",IF(OR(H16>=61,I16=61),"Aprobado","Reprobado")) -> Aprobado
C17: 5 | D17: =+'COA-301 T'!D17:E17 -> Fernandez Choque Karen Carolina | F17: 30 | G17: 57 | H17: =+F17+G17 -> 87 | J17: =IF(H17=0,"Abandono",IF(OR(H17>=61,I17=61),"Aprobado","Reprobado")) -> Aprobado
C18: 6 | D18: =+'COA-301 T'!D18:E18 -> Flores Condarco Eberth Luis | F18: 21 | G18: 45 | H18: =+F18+G18 -> 66 | J18: =IF(H18=0,"Abandono",IF(OR(H18>=61,I18=61),"Aprobado","Reprobado")) -> Aprobado
C19: 7 | D19: =+'COA-301 T'!D19:E19 -> Guarachi Bolivar Ariel Leonel | F19: 0 | G19: 0 | H19: =+F19+G19 -> 0 | J19: =IF(H19=0,"Abandono",IF(OR(H19>=61,I19=61),"Aprobado","Reprobado")) -> Abandono
C20: 8 | D20: =+'COA-301 T'!D20:E20 -> Guarachi Bolivar Omar Rodrigo | F20: 0 | G20: 0 | H20: =+F20+G20 -> 0 | J20: =IF(H20=0,"Abandono",IF(OR(H20>=61,I20=61),"Aprobado","Reprobado")) -> Abandono
C21: 9 | D21: =+'COA-301 T'!D21:E21 -> Lazarte Escobar Cristian Fernando | F21: 0 | G21: 0 | H21: =+F21+G21 -> 0 | J21: =IF(H21=0,"Abandono",IF(OR(H21>=61,I21=61),"Aprobado","Reprobado")) -> Abandono
C22: 10 | D22: =+'COA-301 T'!D22:E22 -> Manzano Huanca David Hernan | F22: 22 | G22: 70 | H22: =+F22+G22 -> 92 | J22: =IF(H22=0,"Abandono",IF(OR(H22>=61,I22=61),"Aprobado","Reprobado")) -> Aprobado
C23: 11 | D23: =+'COA-301 T'!D23:E23 -> Salinas Lopez Elvis Alex | F23: 30 | G23: 51 | H23: =+F23+G23 -> 81 | J23: =IF(H23=0,"Abandono",IF(OR(H23>=61,I23=61),"Aprobado","Reprobado")) -> Aprobado
C24: 12 | D24: =+'COA-301 T'!D24:E24 -> Tellez Ledo Axel Jairo | F24: 10 | G24: 60 | H24: =+F24+G24 -> 70 | J24: =IF(H24=0,"Abandono",IF(OR(H24>=61,I24=61),"Aprobado","Reprobado")) -> Aprobado
G50: RESUMEN | I50: TOTAL | J50: PORCENTAJE
G51: Inscritos | I51: =COUNT(C13:C47) -> 12 | J51: 1
G52: Aprobados | I52: =COUNTIF(J13:K47,"Aprobado") -> 6 | J52: =(I52*J51)/I51 -> 0.5
G53: Reprobados | I53: =COUNTIF(J13:K47,"Reprobado") -> 0 | J53: =(I53*J51)/I51 -> 0
G54: Abandonos | I54: =COUNTIF(J13:J47,"Abandono") -> 6 | J54: =(I54*J51)/I51 -> 0.5
B61: Firma y Sello | F61: Sello de la | I61: Firma y Sello
B62: DIRECTOR ACADEMICO | F62: institución | I62: DOCENTE DE LA MATERIA

Sheet GCI-306 T
A4: INSTITUTO TECNICO DE EDUCACIÓN SUPERIOR "NOVELL"
D5: CARRERA: | E5: CONTADURÍA GENERAL
D6: MENCIÓN:
D7: ÁREA: | E7: COMERCIAL Y SERVICIOS
D8: MATERIA: | E8: =+'GCI-306'!E8:H8 -> GABINETE CONTABLE INFORMÁTICO | I8: SIGLA: | J8: =+'GCI-306'!J8:K8 -> GCI-306
D9: DOCENTE: | E9: LIC. MARIA ELENA MAMANI MACEDA
D10: AÑO/SEMESTRE: | E10: =+'COA-301'!E10:H10 -> TERCER AÑO | I10: GESTIÓN: | J10: =+'COA-301'!J10:K10 -> 2022
C12: Nro. | D12: Apellidos y Nombres | F12: Prom. Ev. Teórica | G12: Prom. Eval. Práctica | H12: Calificación Final | I12: Prueba de Recuper. | J12: Observación
C13: 1 | D13: =+'COA-301 T'!D13:E13 -> Choque Choque Eneida | F13: 0 | G13: 0 | H13: =+F13+G13 -> 0 | J13: =IF(H13=0,"Abandono",IF(OR(H13>=61,I13=61),"Aprobado","Reprobado")) -> Abandono
C14: 2 | D14: =+'COA-301 T'!D14:E14 -> Condori Felipez Nahely | F14: 0 | G14: 0 | H14: =+F14+G14 -> 0 | J14: =IF(H14=0,"Abandono",IF(OR(H14>=61,I14=61),"Aprobado","Reprobado")) -> Abandono
C15: 3 | D15: =+'COA-301 T'!D15:E15 -> Cusi Cruz Ramiro | F15: 0 | G15: 0 | H15: =+F15+G15 -> 0 | J15: =IF(H15=0,"Abandono",IF(OR(H15>=61,I15=61),"Aprobado","Reprobado")) -> Abandono
C16: 4 | D16: =+'COA-301 T'!D16:E16 -> Diaz Soruco Milenka Ingrid | F16: 30 | G16: 54 | H16: =+F16+G16 -> 84 | J16: =IF(H16=0,"Abandono",IF(OR(H16>=61,I16=61),"Aprobado","Reprobado")) -> Aprobado
C17: 5 | D17: =+'COA-301 T'!D17:E17 -> Fernandez Choque Karen Carolina | F17: 30 | G17: 63 | H17: =+F17+G17 -> 93 | J17: =IF(H17=0,"Abandono",IF(OR(H17>=61,I17=61),"Aprobado","Reprobado")) -> Aprobado
C18: 6 | D18: =+'COA-301 T'!D18:E18 -> Flores Condarco Eberth Luis | F18: 25 | G18: 41 | H18: =+F18+G18 -> 66 | J18: =IF(H18=0,"Abandono",IF(OR(H18>=61,I18=61),"Aprobado","Reprobado")) -> Aprobado
C19: 7 | D19: =+'COA-301 T'!D19:E19 -> Guarachi Bolivar Ariel Leonel | F19: 0 | G19: 0 | H19: =+F19+G19 -> 0 | J19: =IF(H19=0,"Abandono",IF(OR(H19>=61,I19=61),"Aprobado","Reprobado")) -> Abandono
C20: 8 | D20: =+'COA-301 T'!D20:E20 -> Guarachi Bolivar Omar Rodrigo | F20: 0 | G20: 0 | H20: =+F20+G20 -> 0 | J20: =IF(H20=0,"Abandono",IF(OR(H20>=61,I20=61),"Aprobado","Reprobado")) -> Abandono
C21: 9 | D21: =+'COA-301 T'!D21:E21 -> Lazarte Escobar Cristian Fernando | F21: 0 | G21: 0 | H21: =+F21+G21 -> 0 | J21: =IF(H21=0,"Abandono",IF(OR(H21>=61,I21=61),"Aprobado","Reprobado")) -> Abandono
C22: 10 | D22: =+'COA-301 T'!D22:E22 -> Manzano Huanca David Hernan | F22: 30 | G22: 70 | H22: =+F22+G22 -> 100 | J22: =IF(H22=0,"Abandono",IF(OR(H22>=61,I22=61),"Aprobado","Reprobado")) -> Aprobado
C23: 11 | D23: =+'COA-301 T'!D23:E23 -> Salinas Lopez Elvis Alex | F23: 30 | G23: 58 | H23: =+F23+G23 -> 88 | J23: =IF(H23=0,"Abandono",IF(OR(H23>=61,I23=61),"Aprobado","Reprobado")) -> Aprobado
C24: 12 | D24: =+'COA-301 T'!D24:E24 -> Tellez Ledo Axel Jairo | F24: 20 | G24: 46 | H24: =+F24+G24 -> 66 | J24: =IF(H24=0,"Abandono",IF(OR(H24>=61,I24=61),"Aprobado","Reprobado")) -> Aprobado
G50: RESUMEN | I50: TOTAL | J50: PORCENTAJE
G51: Inscritos | I51: =COUNT(C13:C47) -> 12 | J51: 1
G52: Aprobados | I52: =COUNTIF(J13:K47,"Aprobado") -> 6 | J52: =(I52*J51)/I51 -> 0.5
G53: Reprobados | I53: =COUNTIF(J13:K47,"Reprobado") -> 0 | J53: =(I53*J51)/I51 -> 0
G54: Abandonos | I54: =COUNTIF(J13:J47,"Abandono") -> 6 | J54: =(I54*J51)/I51 -> 0.5
B61: Firma y Sello | F61: Sello de la | I61: Firma y Sello
B62: DIRECTOR ACADEMICO | F62: institución | I62: DOCENTE DE LA MATERIA

Sheet AEF-307 T
A4: INSTITUTO TECNICO DE EDUCACIÓN SUPERIOR "NOVELL"
D5: CARRERA: | E5: CONTADURÍA GENERAL
D6: MENCIÓN:
D7: ÁREA: | E7: COMERCIAL Y SERVICIOS
D8: MATERIA: | E8: =+'AEF-307'!E8:H8 -> ANÁLISIS E INTERPRETACIONES DE ESTADOS FINANCIEROS | I8: SIGLA: | J8: =+'AEF-307'!J8:K8 -> AEF-307
D9: DOCENTE: | E9: LIC. MARIA ELENA MAMANI MACEDA
D10: AÑO/SEMESTRE: | E10: =+'COA-301'!E10:H10 -> TERCER AÑO | I10: GESTIÓN: | J10: =+'COA-301'!J10:K10 -> 2022
C12: Nro. | D12: Apellidos y Nombres | F12: Prom. Ev. Teórica | G12: Prom. Eval. Práctica | H12: Calificación Final | I12: Prueba de Recuper. | J12: Observación
C13: 1 | D13: =+'COA-301 T'!D13:E13 -> Choque Choque Eneida | F13: 0 | G13: 0 | H13: =+F13+G13 -> 0 | J13: =IF(H13=0,"Abandono",IF(OR(H13>=61,I13=61),"Aprobado","Reprobado")) -> Abandono
C14: 2 | D14: =+'COA-301 T'!D14:E14 -> Condori Felipez Nahely | F14: 0 | G14: 0 | H14: =+F14+G14 -> 0 | J14: =IF(H14=0,"Abandono",IF(OR(H14>=61,I14=61),"Aprobado","Reprobado")) -> Abandono
C15: 3 | D15: =+'COA-301 T'!D15:E15 -> Cusi Cruz Ramiro | F15: 0 | G15: 0 | H15: =+F15+G15 -> 0 | J15: =IF(H15=0,"Abandono",IF(OR(H15>=61,I15=61),"Aprobado","Reprobado")) -> Abandono
C16: 4 | D16: =+'COA-301 T'!D16:E16 -> Diaz Soruco Milenka Ingrid | F16: 23 | G16: 57 | H16: =+F16+G16 -> 80 | J16: =IF(H16=0,"Abandono",IF(OR(H16>=61,I16=61),"Aprobado","Reprobado")) -> Aprobado
C17: 5 | D17: =+'COA-301 T'!D17:E17 -> Fernandez Choque Karen Carolina | F17: 30 | G17: 60 | H17: =+F17+G17 -> 90 | J17: =IF(H17=0,"Abandono",IF(OR(H17>=61,I17=61),"Aprobado","Reprobado")) -> Aprobado
C18: 6 | D18: =+'COA-301 T'!D18:E18 -> Flores Condarco Eberth Luis | F18: 21 | G18: 40 | H18: =+F18+G18 -> 61 | J18: =IF(H18=0,"Abandono",IF(OR(H18>=61,I18=61),"Aprobado","Reprobado")) -> Aprobado
C19: 7 | D19: =+'COA-301 T'!D19:E19 -> Guarachi Bolivar Ariel Leonel | F19: 0 | G19: 0 | H19: =+F19+G19 -> 0 | J19: =IF(H19=0,"Abandono",IF(OR(H19>=61,I19=61),"Aprobado","Reprobado")) -> Abandono
C20: 8 | D20: =+'COA-301 T'!D20:E20 -> Guarachi Bolivar Omar Rodrigo | F20: 0 | G20: 0 | H20: =+F20+G20 -> 0 | J20: =IF(H20=0,"Abandono",IF(OR(H20>=61,I20=61),"Aprobado","Reprobado")) -> Abandono
C21: 9 | D21: =+'COA-301 T'!D21:E21 -> Lazarte Escobar Cristian Fernando | F21: 0 | G21: 0 | H21: =+F21+G21 -> 0 | J21: =IF(H21=0,"Abandono",IF(OR(H21>=61,I21=61),"Aprobado","Reprobado")) -> Abandono
C22: 10 | D22: =+'COA-301 T'!D22:E22 -> Manzano Huanca David Hernan | F22: 30 | G22: 63 | H22: =+F22+G22 -> 93 | J22: =IF(H22=0,"Abandono",IF(OR(H22>=61,I22=61),"Aprobado","Reprobado")) -> Aprobado
C23: 11 | D23: =+'COA-301 T'!D23:E23 -> Salinas Lopez Elvis Alex | F23: 30 | G23: 55 | H23: =+F23+G23 -> 85 | J23: =IF(H23=0,"Abandono",IF(OR(H23>=61,I23=61),"Aprobado","Reprobado")) -> Aprobado
C24: 12 | D24: =+'COA-301 T'!D24:E24 -> Tellez Ledo Axel Jairo | F24: 15 | G24: 30 | H24: =+F24+G24 -> 45 | I24: 61 | J24: =IF(H24=0,"Abandono",IF(OR(H24>=61,I24=61),"Aprobado","Reprobado")) -> Aprobado
G50: RESUMEN | I50: TOTAL | J50: PORCENTAJE
G51: Inscritos | I51: =COUNT(C13:C47) -> 12 | J51: 1
G52: Aprobados | I52: =COUNTIF(J13:K47,"Aprobado") -> 6 | J52: =(I52*J51)/I51 -> 0.5
G53: Reprobados | I53: =COUNTIF(J13:K47,"Reprobado") -> 0 | J53: =(I53*J51)/I51 -> 0
G54: Abandonos | I54: =COUNTIF(J13:J47,"Abandono") -> 6 | J54: =(I54*J51)/I51 -> 0.5
B61: Firma y Sello | F61: Sello de la | I61: Firma y Sello
B62: DIRECTOR ACADEMICO | F62: institución | I62: DOCENTE DE LA MATERIA

Sheet TMG-308 T
A4: INSTITUTO TECNICO DE EDUCACIÓN SUPERIOR "NOVELL"
D5: CARRERA: | E5: CONTADURÍA GENERAL
D6: MENCIÓN:
D7: ÁREA: | E7: COMERCIAL Y SERVICIOS
D8: MATERIA: | E8: =+'TMG-308'!E8:H8 -> TALLER DE MODALIDAD DE GRADUACIÓN | I8: SIGLA: | J8: =+'TMG-308'!J8:K8 -> TMG-308
